Workbook

Sheet How to Use
A1: Paid Search Monthly Tracker
A2: Understory — strategies, deployments, performance recaps, and pre/post reporting
A5: Pre / Post framing
A6: Pre period | B6: Jan–Jun 2026 baseline (before the Jul theme expansion). Use for before-state metrics and narrative.
A7: Post period | B7: Jul 2026 onward (deployment live). Compare against Pre to measure lift / change.
A8: Cutoff | B8: Set via the month dropdown on Monthly Metrics (B14). Config Post Start Date follows that selection.
A10: Tabs
A11: Config | B11: Post start date + client defaults. Change here if the pre/post cutoff moves.
A12: Monthly Overview | B12: Narrative month-by-month view. Rows = strategy / deployment / performance. Columns = months.
A13: Raw Data | B13: Flat log for reporting. One row per entry. Filters + Period (Pre/Post) for comparison.
A14: Monthly Metrics | B14: Numeric scorecard via SUMIFS from Raw Data. Leave formulas alone; enter numbers in Raw Data.
A15: Reporting | B15: Placeholder reporting: monthly trends, Pre vs Post pies/bars. Reporting read chart data tables on this tab.
A17: Workflow
A18: 1. Plan | B18: Monthly Overview → Strategy for the month.
A19: 2. Deploy | B19: Log launches in Overview + Raw Data (Type = Deployment).
A20: 3. Recap | B20: Month-end: Performance Recap rows + Raw Data metrics row.
A21: 4. Compare | B21: Use Reporting reporting and Pre vs Post tables for before/after.
A23: Date Mapping
A24: Rule | B24: 28-day periods. Period 8 = 7/13–8/9/2026. Post Period N maps day-by-day (reversed) to Pre Period N−1.
A25: Selector | B25: On Date Mapping, yellow cell = Post Period. Pre window start/end update via lookup.

Sheet Config
A1: Config
A3: Setting | B3: Value | C3: Notes | E3: Month Label | F3: Month Key | G3: Month Start
A4: Post Start Date | B4: =IFERROR(VLOOKUP('Monthly Metrics'!$B$14,E4:G15,3,FALSE),DATE(2026,7,1)) -> 46204 | C4: Auto from month selector on Monthly Metrics (B14). Dates before = Pre; on/after = Post | E4: Jan 2026 | F4: 2026-01 | G4: 46023
A5: Primary Client | B5: Red Robin | C5: Default client for sample / reporting | E5: Feb 2026 | F5: 2026-02 | G5: 46054
A6: Primary Platform | B6: Google Ads | C6: Default platform | E6: Mar 2026 | F6: 2026-03 | G6: 46082
A7: Pre Label | B7: Pre | C7: Used in Period column + Pre/Post table | E7: Apr 2026 | F7: 2026-04 | G7: 46113
A8: Post Label | B8: Post | C8: Used in Period column + Pre/Post table | E8: May 2026 | F8: 2026-05 | G8: 46143
A9: Year | B9: 2026 | C9: Month headers year | E9: Jun 2026 | F9: 2026-06 | G9: 46174
E10: Jul 2026 | F10: 2026-07 | G10: 46204
A11: Change the Post start month on Monthly Metrics (dropdown in B14). Pre/Post summary and Raw Data Period tags update from that selection.
A12: Date Mapping sheet holds the full 2026 day-level Pre/Post pairs (Period 8 sample = 7/13–8/9 ↔ Period 7 = 6/15–7/12).
E13: Oct 2026 | F13: 2026-10 | G13: 46296
E14: Nov 2026 | F14: 2026-11 | G14: 46327
E15: Dec 2026 | F15: 2026-12 | G15: 46357

Sheet Date Mapping
A1: Pre / Post Date Mapping — 2026
A2: 28-day periods anchored to Period 8 = 7/13/2026–8/9/2026. Each Post date maps to the mirrored day in the prior period (Post day 1 ↔ Pre last day, …, Post last day ↔ Pre first day).
A4: Period index
A5: Period | B5: Start | C5: End | D5: Days | E5: Role vs prior
A6: 0 | B6: 45992 | C6: 46019 | D6: 28 | E6: Pre for Period 1
A7: 1 | B7: 46020 | C7: 46047 | D7: 28 | E7: Post (maps ← Period 0); Pre for Period 2
A8: 2 | B8: 46048 | C8: 46075 | D8: 28 | E8: Post (maps ← Period 1); Pre for Period 3
A9: 3 | B9: 46076 | C9: 46103 | D9: 28 | E9: Post (maps ← Period 2); Pre for Period 4
A10: 4 | B10: 46104 | C10: 46131 | D10: 28 | E10: Post (maps ← Period 3); Pre for Period 5
A11: 5 | B11: 46132 | C11: 46159 | D11: 28 | E11: Post (maps ← Period 4); Pre for Period 6
A12: 6 | B12: 46160 | C12: 46187 | D12: 28 | E12: Post (maps ← Period 5); Pre for Period 7
A13: 7 | B13: 46188 | C13: 46215 | D13: 28 | E13: Post (maps ← Period 6); Pre for Period 8
A14: 8 | B14: 46216 | C14: 46243 | D14: 28 | E14: Post (maps ← Period 7); Pre for Period 9
A15: 9 | B15: 46244 | C15: 46271 | D15: 28 | E15: Post (maps ← Period 8); Pre for Period 10
A16: 10 | B16: 46272 | C16: 46299 | D16: 28 | E16: Post (maps ← Period 9); Pre for Period 11
A17: 11 | B17: 46300 | C17: 46327 | D17: 28 | E17: Post (maps ← Period 10); Pre for Period 12
... A20: 14 | B20: 46384 | C20: 46411 | D20: 28 | E20: Post (maps ← Period 13)
A22: Day-level mapping (Post date in 2026 → Pre date) | H22: Lookup helpers
A23: Post Period | B23: Post Date | C23: Pre Period | D23: Pre Date | E23: Post Window | F23: Pre Window | H23: Select Post Period | I23: 8
A24: 1 | B24: 46023 | C24: 0 | D24: 46016 | E24: 12/29/2025–1/25/2026 | F24: 12/1/2025–12/28/2025 | H24: Post window start | I24: =IFERROR(_xludf.MINIFS(B24:B388,A24:A388,I23),"")
A25: 1 | B25: 46024 | C25: 0 | D25: 46015 | E25: 12/29/2025–1/25/2026 | F25: 12/1/2025–12/28/2025 | H25: Post window end | I25: =IFERROR(_xludf.MAXIFS(B24:B388,A24:A388,I23),"")
A26: 1 | B26: 46025 | C26: 0 | D26: 46014 | E26: 12/29/2025–1/25/2026 | F26: 12/1/2025–12/28/2025 | H26: Pre period # | I26: =IFERROR(INDEX(C24:C388,MATCH(I23,A24:A388,0)),"") -> 7
A27: 1 | B27: 46026 | C27: 0 | D27: 46013 | E27: 12/29/2025–1/25/2026 | F27: 12/1/2025–12/28/2025 | H27: Pre window start | I27: =IFERROR(_xludf.MINIFS(D24:D388,A24:A388,I23),"")
A28: 1 | B28: 46027 | C28: 0 | D28: 46012 | E28: 12/29/2025–1/25/2026 | F28: 12/1/2025–12/28/2025 | H28: Pre window end | I28: =IFERROR(_xludf.MAXIFS(D24:D388,A24:A388,I23),"")
A29: 1 | B29: 46028 | C29: 0 | D29: 46011 | E29: 12/29/2025–1/25/2026 | F29: 12/1/2025–12/28/2025 | H29: Day count | I29: =IFERROR(COUNTIF(A24:A388,I23),"") -> 28
A30: 1 | B30: 46029 | C30: 0 | D30: 46010 | E30: 12/29/2025–1/25/2026 | F30: 12/1/2025–12/28/2025
A31: 1 | B31: 46030 | C31: 0 | D31: 46009 | E31: 12/29/2025–1/25/2026 | F31: 12/1/2025–12/28/2025 | H31: Change I23 to pick a Post period — Pre window looks up automatically.
A32: 1 | B32: 46031 | C32: 0 | D32: 46008 | E32: 12/29/2025–1/25/2026 | F32: 12/1/2025–12/28/2025
A33: 1 | B33: 46032 | C33: 0 | D33: 46007 | E33: 12/29/2025–1/25/2026 | F33: 12/1/2025–12/28/2025
A34: 1 | B34: 46033 | C34: 0 | D34: 46006 | E34: 12/29/2025–1/25/2026 | F34: 12/1/2025–12/28/2025
A35: 1 | B35: 46034 | C35: 0 | D35: 46005 | E35: 12/29/2025–1/25/2026 | F35: 12/1/2025–12/28/2025
A36: 1 | B36: 46035 | C36: 0 | D36: 46004 | E36: 12/29/2025–1/25/2026 | F36: 12/1/2025–12/28/2025
A37: 1 | B37: 46036 | C37: 0 | D37: 46003 | E37: 12/29/2025–1/25/2026 | F37: 12/1/2025–12/28/2025
A38: 1 | B38: 46037 | C38: 0 | D38: 46002 | E38: 12/29/2025–1/25/2026 | F38: 12/1/2025–12/28/2025
A39: 1 | B39: 46038 | C39: 0 | D39: 46001 | E39: 12/29/2025–1/25/2026 | F39: 12/1/2025–12/28/2025
A40: 1 | B40: 46039 | C40: 0 | D40: 46000 | E40: 12/29/2025–1/25/2026 | F40: 12/1/2025–12/28/2025
A41: 1 | B41: 46040 | C41: 0 | D41: 45999 | E41: 12/29/2025–1/25/2026 | F41: 12/1/2025–12/28/2025
A42: 1 | B42: 46041 | C42: 0 | D42: 45998 | E42: 12/29/2025–1/25/2026 | F42: 12/1/2025–12/28/2025
A43: 1 | B43: 46042 | C43: 0 | D43: 45997 | E43: 12/29/2025–1/25/2026 | F43: 12/1/2025–12/28/2025
... A388: 14 | B388: 46387 | C388: 13 | D388: 46380 | E388: 12/28/2026–1/24/2027 | F388: 11/30/2026–12/27/2026

Sheet Campaign Mapping
A1: Store ID | B1: Campaign | C1: Store ID | D1: Campaign type | E1: Final URL Expansion
A2: 466 | B2: RR_Surface_PMAX_Franch_LVRB_Value-Mix_Adult-Non-Burger_466_Exeter-Commons | C2: 466 | D2: Performance Max | E2: No
A3: 496 | B3: RR_Surface_PMAX_Franch_Ansara_Value-Mix_Adult-Non-Burger_496_Holland | C3: 496 | D3: Performance Max | E3: No
A4: 499 | B4: RR_Surface_PMAX_Franch_Ansara_Value-Mix_Adult-Non-Burger_499_Ann-Arbor | C4: 499 | D4: Performance Max | E4: No
A5: 329 | B5: RR_Surface_PMAX_Franch_LVRB_Value-Mix_Adult-Non-Burger_329_Silver-Spring | C5: 329 | D5: Performance Max | E5: No
A6: 339 | B6: RR_Surface_PMAX_Franch_LVRB_Value-Mix_Adult-Non-Burger_339_Stroudsburg | C6: 339 | D6: Performance Max | E6: No
A7: 761 | B7: RR_Surface_PMAX_Franch_Ansara_Value-Mix_Adult-Non-Burger_761_Rossford | C7: 761 | D7: Performance Max | E7: No
A8: 326 | B8: RR_Surface_PMAX_Franch_LVRB_Value-Mix_Adult-Non-Burger_326_Northampton-Crossings | C8: 326 | D8: Performance Max | E8: No
A9: 334 | B9: RR_Surface_PMAX_Franch_LVRB_Value-Mix_Adult-Non-Burger_334_Airport-Road | C9: 334 | D9: Performance Max | E9: No
A10: 468 | B10: RR_Surface_PMAX_Franch_LVRB_Value-Mix_Adult-Non-Burger_468_Hamburg | C10: 468 | D10: Performance Max | E10: No
A11: 495 | B11: RR_Surface_PMAX_Franch_Ansara_Value-Mix_Adult-Non-Burger_495_Woodland-Mall-(Kentwood) | C11: 495 | D11: Performance Max | E11: No
A12: 498 | B12: RR_Surface_PMAX_Franch_Ansara_Value-Mix_Adult-Non-Burger_498_Fallen-Timbers | C12: 498 | D12: Performance Max | E12: No
A13: 384 | B13: RR_Surface_PMAX_Franch_Ansara_Value-Mix_Adult-Non-Burger_384_Toledo | C13: 384 | D13: Performance Max | E13: No
... A23: 327 | B23: RR_Surface_PMAX_Franch_LVRB_Value-Mix_Adult-Non-Burger_327_Hershey | C23: 327 | D23: Performance Max | E23: No
A24: 386 | B24: RR_Surface_PMAX_Franch_Ansara_Value-Mix_Adult-Non-Burger_386_Delta-Township | C24: 386 | D24: Performance Max | E24: 386
A25: 380 | B25: RR_Surface_PMAX_Franch_Ansara_Value-Mix_Adult-Non-Burger_380_Roseville | C25: 380 | D25: Performance Max | E25: No
A26: 382 | B26: RR_Surface_PMAX_Franch_Ansara_Value-Mix_Adult-Non-Burger_382_Brighton | C26: 382 | D26: Performance Max | E26: No
A27: 324 | B27: RR_Surface_PMAX_Franch_LVRB_Value-Mix_Adult-Non-Burger_324_Quakertown | C27: 324 | D27: Performance Max | E27: No
A28: 491 | B28: RR_Surface_PMAX_Franch_LVRB_Value-Mix_Adult-Non-Burger_491_York | C28: 491 | D28: Performance Max | E28: No
A29: 335 | B29: RR_Surface_PMAX_Franch_LVRB_Value-Mix_Adult-Non-Burger_335_Wilkes-Barre | C29: 335 | D29: Performance Max | E29: No
A30: 388 | B30: RR_Surface_PMAX_Franch_Ansara_Value-Mix_Adult-Non-Burger_388_Flint | C30: 388 | D30: Performance Max | E30: No
A31: 494 | B31: RR_Surface_PMAX_Franch_Ansara_Value-Mix_Adult-Non-Burger_494_Commerce | C31: 494 | D31: Performance Max | E31: No
A32: 465 | B32: RR_Surface_PMAX_Franch_LVRB_Value-Mix_Adult-Non-Burger_465_Selinsgrove | C32: 465 | D32: Performance Max | E32: No
A33: 497 | B33: RR_Surface_PMAX_Franch_Ansara_Value-Mix_Adult-Non-Burger_497_Muskegon | C33: 497 | D33: Performance Max | E33: No
A34: 378 | B34: RR_Surface_PMAX_Franch_Ansara_Value-Mix_Adult-Non-Burger_378_Southgate | C34: 378 | D34: Performance Max | E34: No
A35: 389 | B35: RR_Surface_PMAX_Franch_Ansara_Value-Mix_Adult-Non-Burger_389_Troy | C35: 389 | D35: Performance Max | E35: No
A36: 338 | B36: RR_Surface_PMAX_Franch_LVRB_Value-Mix_Adult-Non-Burger_338_Carlisle-Crossings | C36: 338 | D36: Performance Max | E36: No
... A43: 337 | B43: RR_Surface_PMAX_Franch_LVRB_Value-Mix_Adult-Non-Burger_337_Dickson-City | C43: 337 | D43: Performance Max | E43: No
B44: RR_Surface_SEM_Brand_Donatos | D44: Search | E44: No
B45: RR_Surface_PMAX_Donatos | D45: Performance Max | E45: No
A46: 746 | B46: RR_Surface_Youtube_Everyday-Non-Burger_Value-Mix_746_Metro-Center | C46: 746 | D46: Demand Gen | E46: No
A47: 459 | B47: RR_Surface_Youtube_Core-Bar/Adult_Value-Mix_459_Silverado-Ranch | C47: 459 | D47: Demand Gen | E47: No
A48: 731 | B48: RR_Surface_Youtube_Corp_Core-Burger_Value-Mix_731_Chubbuck | C48: 731 | D48: Demand Gen | E48: No
A49: 458 | B49: RR_Surface_Youtube_Core-Bar/Adult_Value-Mix_458_Summerlin | C49: 458 | D49: Demand Gen | E49: No
A50: 429 | B50: RR_Surface_Youtube_Corp_Growing-Burger_Value-Mix_429_Oswego | C50: 429 | D50: Demand Gen | E50: No
A51: 62 | B51: RR_Surface_Youtube_Everyday-Non-Burger_Value-Mix_62_Powers | C51: 62 | D51: Demand Gen | E51: No
A52: 15 | B52: RR_Surface_Youtube_Everyday-Non-Burger_Value-Mix_15_Broadmoor | C52: 15 | D52: Demand Gen | E52: No
A53: 436 | B53: RR_Surface_Youtube_Corp_Growing-Burger_Value-Mix_436_Metropolis | C53: 436 | D53: Demand Gen | E53: No
A54: 650 | B54: RR_Surface_Youtube_Corp_Growing-Burger_Value-Mix_650_Valparaiso | C54: 650 | D54: Demand Gen | E54: No
A55: 89 | B55: RR_Surface_Youtube_Corp_Bar-Driven-Promo_Value-Mix_89_Corona | C55: 89 | D55: Demand Gen | E55: No
...

Sheet Monthly Overview
A1: Paid Search — Monthly Strategy / Deployments / Performance
A2: Period tags below follow the Jul deploy default for layout. Authoritative Pre/Post cut for metrics = Monthly Metrics month dropdown (B14).
A3: Section | B3: Item | C3: Aug 2026 | D3: Sep 2026 | E3: Oct 2026 | F3: Nov 2026 | G3: Dec 2026
A4: Period | C4: 8 & 9 | D4: 9 & 10 | E4: 10 & 11 | F4: 11 & 12 | G4: 12 & 13
A5: STRATEGY | B5: Monthly focus / thesis | C5: Final URL Expansion Store Visits vs. Local Actions Demand Gen (Maps Only)
B6: Audience & geo posture
B7: Budget allocation notes
B8: Themes / keywords / negatives
B9: Creative / offer direction
B10: Risks & watchouts
A11: DEPLOYMENTS | B11: Campaigns launched / paused
B12: Ads / RSAs / assets shipped
B13: Bidding / budget changes
B14: Landing page / tracking changes
B15: Experiments started / concluded
B16: Other ops changes
A17: PERFORMANCE RECAP | B17: What worked
B18: What underperformed
B19: Insights & learnings
B20: Client / stakeholder notes
B21: Priorities for next month
A23: Tip: Pre columns are cool-tinted, Post are white, current month is mint. Keep cells short; full detail + metrics live in Raw Data.

Sheet Raw Data
A1: Entry ID | B1: Date | C1: Month Key | D1: Month Label | E1: Period | F1: Type | G1: Client / Account | H1: Platform | I1: Campaign | J1: Ad Group / Theme | K1: Status | L1: Description | M1: Spend | N1: Impressions | O1: Clicks | P1: CTR % | Q1: Conversions | R1: Conv. Rate % | S1: CPA | T1: ROAS | U1: Owner | V1: Doc / Link | W1: Notes
A2: 1 | B2: 46053 | C2: =IF(B2="","",TEXT(B2,"YYYY-MM")) -> 2026-01 | D2: =IF(B2="","",TEXT(B2,"MMM YYYY")) -> Jan 2026 | E2: =IF(B2="","",IF(B2<Config!$B$4,Config!$B$7,Config!$B$8)) -> Pre | F2: Performance Recap | G2: Red Robin | H2: Google Ads | I2: All Search | K2: Recap | L2: Monthly performance recap — Jan 2026 | M2: 4200 | N2: 185000 | O2: 6200 | P2: =IF(OR(N2="",O2=""),"",IF(N2=0,"",O2/N2*100)) -> 3.3513514 | Q2: 148 | R2: =IF(OR(O2="",Q2=""),"",IF(O2=0,"",Q2/O2*100)) -> 2.3870968 | S2: =IF(OR(M2="",Q2=""),"",IF(Q2=0,"",M2/Q2)) -> 28.378378 | T2: 3.1 | U2: Skye | W2: Pre baseline — Jan
A3: 2 | B3: 46081 | C3: =IF(B3="","",TEXT(B3,"YYYY-MM")) -> 2026-02 | D3: =IF(B3="","",TEXT(B3,"MMM YYYY")) -> Feb 2026 | E3: =IF(B3="","",IF(B3<Config!$B$4,Config!$B$7,Config!$B$8)) -> Pre | F3: Performance Recap | G3: Red Robin | H3: Google Ads | I3: All Search | K3: Recap | L3: Monthly performance recap — Feb 2026 | M3: 4100 | N3: 178000 | O3: 6050 | P3: =IF(OR(N3="",O3=""),"",IF(N3=0,"",O3/N3*100)) -> 3.3988764 | Q3: 142 | R3: =IF(OR(O3="",Q3=""),"",IF(O3=0,"",Q3/O3*100)) -> 2.3471074 | S3: =IF(OR(M3="",Q3=""),"",IF(Q3=0,"",M3/Q3)) -> 28.873239 | T3: 3 | U3: Skye | W3: Pre baseline — Feb
A4: 3 | B4: 46112 | C4: =IF(B4="","",TEXT(B4,"YYYY-MM")) -> 2026-03 | D4: =IF(B4="","",TEXT(B4,"MMM YYYY")) -> Mar 2026 | E4: =IF(B4="","",IF(B4<Config!$B$4,Config!$B$7,Config!$B$8)) -> Pre | F4: Performance Recap | G4: Red Robin | H4: Google Ads | I4: All Search | K4: Recap | L4: Monthly performance recap — Mar 2026 | M4: 4450 | N4: 192000 | O4: 6400 | P4: =IF(OR(N4="",O4=""),"",IF(N4=0,"",O4/N4*100)) -> 3.3333333 | Q4: 155 | R4: =IF(OR(O4="",Q4=""),"",IF(O4=0,"",Q4/O4*100)) -> 2.421875 | S4: =IF(OR(M4="",Q4=""),"",IF(Q4=0,"",M4/Q4)) -> 28.709677 | T4: 3.2 | U4: Skye | W4: Pre baseline — Mar
A5: 4 | B5: 46142 | C5: =IF(B5="","",TEXT(B5,"YYYY-MM")) -> 2026-04 | D5: =IF(B5="","",TEXT(B5,"MMM YYYY")) -> Apr 2026 | E5: =IF(B5="","",IF(B5<Config!$B$4,Config!$B$7,Config!$B$8)) -> Pre | F5: Performance Recap | G5: Red Robin | H5: Google Ads | I5: All Search | K5: Recap | L5: Monthly performance recap — Apr 2026 | M5: 4600 | N5: 198000 | O5: 6550 | P5: =IF(OR(N5="",O5=""),"",IF(N5=0,"",O5/N5*100)) -> 3.3080808 | Q5: 160 | R5: =IF(OR(O5="",Q5=""),"",IF(O5=0,"",Q5/O5*100)) -> 2.4427481 | S5: =IF(OR(M5="",Q5=""),"",IF(Q5=0,"",M5/Q5)) -> 28.75 | T5: 3.15 | U5: Skye | W5: Pre baseline — Apr
A6: 5 | B6: 46173 | C6: =IF(B6="","",TEXT(B6,"YYYY-MM")) -> 2026-05 | D6: =IF(B6="","",TEXT(B6,"MMM YYYY")) -> May 2026 | E6: =IF(B6="","",IF(B6<Config!$B$4,Config!$B$7,Config!$B$8)) -> Pre | F6: Performance Recap | G6: Red Robin | H6: Google Ads | I6: All Search | K6: Recap | L6: Monthly performance recap — May 2026 | M6: 4550 | N6: 201000 | O6: 6620 | P6: =IF(OR(N6="",O6=""),"",IF(N6=0,"",O6/N6*100)) -> 3.2935323 | Q6: 158 | R6: =IF(OR(O6="",Q6=""),"",IF(O6=0,"",Q6/O6*100)) -> 2.3867069 | S6: =IF(OR(M6="",Q6=""),"",IF(Q6=0,"",M6/Q6)) -> 28.797468 | T6: 3.2 | U6: Skye | W6: Pre baseline — May
A7: 6 | B7: 46203 | C7: =IF(B7="","",TEXT(B7,"YYYY-MM")) -> 2026-06 | D7: =IF(B7="","",TEXT(B7,"MMM YYYY")) -> Jun 2026 | E7: =IF(B7="","",IF(B7<Config!$B$4,Config!$B$7,Config!$B$8)) -> Pre | F7: Performance Recap | G7: Red Robin | H7: Google Ads | I7: All Search | K7: Recap | L7: Monthly performance recap — Jun 2026 | M7: 4700 | N7: 205000 | O7: 6800 | P7: =IF(OR(N7="",O7=""),"",IF(N7=0,"",O7/N7*100)) -> 3.3170732 | Q7: 165 | R7: =IF(OR(O7="",Q7=""),"",IF(O7=0,"",Q7/O7*100)) -> 2.4264706 | S7: =IF(OR(M7="",Q7=""),"",IF(Q7=0,"",M7/Q7)) -> 28.484848 | T7: 3.25 | U7: Skye | W7: Pre baseline — Jun (last Pre month)
A8: 7 | B8: 46230 | C8: =IF(B8="","",TEXT(B8,"YYYY-MM")) -> 2026-07 | D8: =IF(B8="","",TEXT(B8,"MMM YYYY")) -> Jul 2026 | E8: =IF(B8="","",IF(B8<Config!$B$4,Config!$B$7,Config!$B$8)) -> Post | F8: Performance Recap | G8: Red Robin | H8: Google Ads | I8: All Search | K8: Recap | L8: Monthly performance recap — Jul 2026 | M8: 5100 | N8: 228000 | O8: 7450 | P8: =IF(OR(N8="",O8=""),"",IF(N8=0,"",O8/N8*100)) -> 3.2675439 | Q8: 188 | R8: =IF(OR(O8="",Q8=""),"",IF(O8=0,"",Q8/O8*100)) -> 2.5234899 | S8: =IF(OR(M8="",Q8=""),"",IF(Q8=0,"",M8/Q8)) -> 27.12766 | T8: 3.55 | U8: Skye | W8: Post — mid-Jul after theme expansion
A9: 8 | B9: 46188 | C9: =IF(B9="","",TEXT(B9,"YYYY-MM")) -> 2026-06 | D9: =IF(B9="","",TEXT(B9,"MMM YYYY")) -> Jun 2026 | E9: =IF(B9="","",IF(B9<Config!$B$4,Config!$B$7,Config!$B$8)) -> Pre | F9: Strategy | G9: Red Robin | H9: Google Ads | K9: Planned | L9: Finalize Family + chicken theme expansion for Jul Post start | P9: =IF(OR(N9="",O9=""),"",IF(N9=0,"",O9/N9*100)) | R9: =IF(OR(O9="",Q9=""),"",IF(O9=0,"",Q9/O9*100)) | S9: =IF(OR(M9="",Q9=""),"",IF(Q9=0,"",M9/Q9)) | U9: Skye | W9: Brief ready; deploy Jul 1 week
A10: 9 | B10: 46204 | C10: =IF(B10="","",TEXT(B10,"YYYY-MM")) -> 2026-07 | D10: =IF(B10="","",TEXT(B10,"MMM YYYY")) -> Jul 2026 | E10: =IF(B10="","",IF(B10<Config!$B$4,Config!$B$7,Config!$B$8)) -> Post | F10: Strategy | G10: Red Robin | H10: Google Ads | K10: Planned | L10: Post period live — Family + chicken themes; dinner occasion focus | P10: =IF(OR(N10="",O10=""),"",IF(N10=0,"",O10/N10*100)) | R10: =IF(OR(O10="",Q10=""),"",IF(O10=0,"",Q10/O10*100)) | S10: =IF(OR(M10="",Q10=""),"",IF(Q10=0,"",M10/Q10)) | U10: Skye | W10: Seeded from Search Themes Review
A11: 10 | B11: 46211 | C11: =IF(B11="","",TEXT(B11,"YYYY-MM")) -> 2026-07 | D11: =IF(B11="","",TEXT(B11,"MMM YYYY")) -> Jul 2026 | E11: =IF(B11="","",IF(B11<Config!$B$4,Config!$B$7,Config!$B$8)) -> Post | F11: Deployment | G11: Red Robin | H11: Google Ads | I11: Non-Brand Search | J11: Family & Kids | K11: Live | L11: Launched 7 new Family & Kids root themes | M11: 850 | N11: 42000 | O11: 1400 | P11: =IF(OR(N11="",O11=""),"",IF(N11=0,"",O11/N11*100)) -> 3.3333333 | Q11: 28 | R11: =IF(OR(O11="",Q11=""),"",IF(O11=0,"",Q11/O11*100)) -> 2 | S11: =IF(OR(M11="",Q11=""),"",IF(Q11=0,"",M11/Q11)) -> 30.357143 | T11: 3.8 | U11: Skye | W11: Theme deploy week 1
A12: 11 | B12: 46213 | C12: =IF(B12="","",TEXT(B12,"YYYY-MM")) -> 2026-07 | D12: =IF(B12="","",TEXT(B12,"MMM YYYY")) -> Jul 2026 | E12: =IF(B12="","",IF(B12<Config!$B$4,Config!$B$7,Config!$B$8)) -> Post | F12: Deployment | G12: Red Robin | H12: Google Ads | I12: Non-Brand Search | J12: Chicken | K12: Live | L12: Launched chicken product root themes | M12: 620 | N12: 31000 | O12: 980 | P12: =IF(OR(N12="",O12=""),"",IF(N12=0,"",O12/N12*100)) -> 3.1612903 | Q12: 19 | R12: =IF(OR(O12="",Q12=""),"",IF(O12=0,"",Q12/O12*100)) -> 1.9387755 | S12: =IF(OR(M12="",Q12=""),"",IF(Q12=0,"",M12/Q12)) -> 32.631579 | T12: 3.4 | U12: Skye | W12: Theme deploy week 1
A13: =IF(B13="","",ROW()-1) | C13: =IF(B13="","",TEXT(B13,"YYYY-MM")) | D13: =IF(B13="","",TEXT(B13,"MMM YYYY")) | E13: =IF(B13="","",IF(B13<Config!$B$4,Config!$B$7,Config!$B$8)) | P13: =IF(OR(N13="",O13=""),"",IF(N13=0,"",O13/N13*100)) | R13: =IF(OR(O13="",Q13=""),"",IF(O13=0,"",Q13/O13*100)) | S13: =IF(OR(M13="",Q13=""),"",IF(Q13=0,"",M13/Q13))
A14: =IF(B14="","",ROW()-1) | C14: =IF(B14="","",TEXT(B14,"YYYY-MM")) | D14: =IF(B14="","",TEXT(B14,"MMM YYYY")) | E14: =IF(B14="","",IF(B14<Config!$B$4,Config!$B$7,Config!$B$8)) | P14: =IF(OR(N14="",O14=""),"",IF(N14=0,"",O14/N14*100)) | R14: =IF(OR(O14="",Q14=""),"",IF(O14=0,"",Q14/O14*100)) | S14: =IF(OR(M14="",Q14=""),"",IF(Q14=0,"",M14/Q14))
A15: =IF(B15="","",ROW()-1) | C15: =IF(B15="","",TEXT(B15,"YYYY-MM")) | D15: =IF(B15="","",TEXT(B15,"MMM YYYY")) | E15: =IF(B15="","",IF(B15<Config!$B$4,Config!$B$7,Config!$B$8)) | P15: =IF(OR(N15="",O15=""),"",IF(N15=0,"",O15/N15*100)) | R15: =IF(OR(O15="",Q15=""),"",IF(O15=0,"",Q15/O15*100)) | S15: =IF(OR(M15="",Q15=""),"",IF(Q15=0,"",M15/Q15))
A16: =IF(B16="","",ROW()-1) | C16: =IF(B16="","",TEXT(B16,"YYYY-MM")) | D16: =IF(B16="","",TEXT(B16,"MMM YYYY")) | E16: =IF(B16="","",IF(B16<Config!$B$4,Config!$B$7,Config!$B$8)) | P16: =IF(OR(N16="",O16=""),"",IF(N16=0,"",O16/N16*100)) | R16: =IF(OR(O16="",Q16=""),"",IF(O16=0,"",Q16/O16*100)) | S16: =IF(OR(M16="",Q16=""),"",IF(Q16=0,"",M16/Q16))
A17: =IF(B17="","",ROW()-1) | C17: =IF(B17="","",TEXT(B17,"YYYY-MM")) | D17: =IF(B17="","",TEXT(B17,"MMM YYYY")) | E17: =IF(B17="","",IF(B17<Config!$B$4,Config!$B$7,Config!$B$8)) | P17: =IF(OR(N17="",O17=""),"",IF(N17=0,"",O17/N17*100)) | R17: =IF(OR(O17="",Q17=""),"",IF(O17=0,"",Q17/O17*100)) | S17: =IF(OR(M17="",Q17=""),"",IF(Q17=0,"",M17/Q17))
A18: =IF(B18="","",ROW()-1) | C18: =IF(B18="","",TEXT(B18,"YYYY-MM")) | D18: =IF(B18="","",TEXT(B18,"MMM YYYY")) | E18: =IF(B18="","",IF(B18<Config!$B$4,Config!$B$7,Config!$B$8)) | P18: =IF(OR(N18="",O18=""),"",IF(N18=0,"",O18/N18*100)) | R18: =IF(OR(O18="",Q18=""),"",IF(O18=0,"",Q18/O18*100)) | S18: =IF(OR(M18="",Q18=""),"",IF(Q18=0,"",M18/Q18))
A19: =IF(B19="","",ROW()-1) | C19: =IF(B19="","",TEXT(B19,"YYYY-MM")) | D19: =IF(B19="","",TEXT(B19,"MMM YYYY")) | E19: =IF(B19="","",IF(B19<Config!$B$4,Config!$B$7,Config!$B$8)) | P19: =IF(OR(N19="",O19=""),"",IF(N19=0,"",O19/N19*100)) | R19: =IF(OR(O19="",Q19=""),"",IF(O19=0,"",Q19/O19*100)) | S19: =IF(OR(M19="",Q19=""),"",IF(Q19=0,"",M19/Q19))
A20: =IF(B20="","",ROW()-1) | C20: =IF(B20="","",TEXT(B20,"YYYY-MM")) | D20: =IF(B20="","",TEXT(B20,"MMM YYYY")) | E20: =IF(B20="","",IF(B20<Config!$B$4,Config!$B$7,Config!$B$8)) | P20: =IF(OR(N20="",O20=""),"",IF(N20=0,"",O20/N20*100)) | R20: =IF(OR(O20="",Q20=""),"",IF(O20=0,"",Q20/O20*100)) | S20: =IF(OR(M20="",Q20=""),"",IF(Q20=0,"",M20/Q20))
A21: =IF(B21="","",ROW()-1) | C21: =IF(B21="","",TEXT(B21,"YYYY-MM")) | D21: =IF(B21="","",TEXT(B21,"MMM YYYY")) | E21: =IF(B21="","",IF(B21<Config!$B$4,Config!$B$7,Config!$B$8)) | P21: =IF(OR(N21="",O21=""),"",IF(N21=0,"",O21/N21*100)) | R21: =IF(OR(O21="",Q21=""),"",IF(O21=0,"",Q21/O21*100)) | S21: =IF(OR(M21="",Q21=""),"",IF(Q21=0,"",M21/Q21))
A22: =IF(B22="","",ROW()-1) | C22: =IF(B22="","",TEXT(B22,"YYYY-MM")) | D22: =IF(B22="","",TEXT(B22,"MMM YYYY")) | E22: =IF(B22="","",IF(B22<Config!$B$4,Config!$B$7,Config!$B$8)) | P22: =IF(OR(N22="",O22=""),"",IF(N22=0,"",O22/N22*100)) | R22: =IF(OR(O22="",Q22=""),"",IF(O22=0,"",Q22/O22*100)) | S22: =IF(OR(M22="",Q22=""),"",IF(Q22=0,"",M22/Q22))
A23: =IF(B23="","",ROW()-1) | C23: =IF(B23="","",TEXT(B23,"YYYY-MM")) | D23: =IF(B23="","",TEXT(B23,"MMM YYYY")) | E23: =IF(B23="","",IF(B23<Config!$B$4,Config!$B$7,Config!$B$8)) | P23: =IF(OR(N23="",O23=""),"",IF(N23=0,"",O23/N23*100)) | R23: =IF(OR(O23="",Q23=""),"",IF(O23=0,"",Q23/O23*100)) | S23: =IF(OR(M23="",Q23=""),"",IF(Q23=0,"",M23/Q23))
A24: =IF(B24="","",ROW()-1) | C24: =IF(B24="","",TEXT(B24,"YYYY-MM")) | D24: =IF(B24="","",TEXT(B24,"MMM YYYY")) | E24: =IF(B24="","",IF(B24<Config!$B$4,Config!$B$7,Config!$B$8)) | P24: =IF(OR(N24="",O24=""),"",IF(N24=0,"",O24/N24*100)) | R24: =IF(OR(O24="",Q24=""),"",IF(O24=0,"",Q24/O24*100)) | S24: =IF(OR(M24="",Q24=""),"",IF(Q24=0,"",M24/Q24))
... A200: =IF(B200="","",ROW()-1) | C200: =IF(B200="","",TEXT(B200,"YYYY-MM")) | D200: =IF(B200="","",TEXT(B200,"MMM YYYY")) | E200: =IF(B200="","",IF(B200<Config!$B$4,Config!$B$7,Config!$B$8)) | P200: =IF(OR(N200="",O200=""),"",IF(N200=0,"",O200/N200*100)) | R200: =IF(OR(O200="",Q200=""),"",IF(O200=0,"",Q200/O200*100)) | S200: =IF(OR(M200="",Q200=""),"",IF(Q200=0,"",M200/Q200))

Sheet Monthly Metrics
A1: Monthly Performance Scorecard (from Raw Data)
A2: Pick Post start month in B14. Pre = months before selection; Post = selected month through Dec. Scorecard above rolls up from Raw Data.
A3: Period | B3: =IF($B$14="","",IF((COLUMN()-1)<MATCH($B$14,$B$4:$M$4,0),Config!$B$7,Config!$B$8)) -> Pre | C3: =IF($B$14="","",IF((COLUMN()-1)<MATCH($B$14,$B$4:$M$4,0),Config!$B$7,Config!$B$8)) -> Pre | D3: =IF($B$14="","",IF((COLUMN()-1)<MATCH($B$14,$B$4:$M$4,0),Config!$B$7,Config!$B$8)) -> Pre | E3: =IF($B$14="","",IF((COLUMN()-1)<MATCH($B$14,$B$4:$M$4,0),Config!$B$7,Config!$B$8)) -> Pre | F3: =IF($B$14="","",IF((COLUMN()-1)<MATCH($B$14,$B$4:$M$4,0),Config!$B$7,Config!$B$8)) -> Pre | G3: =IF($B$14="","",IF((COLUMN()-1)<MATCH($B$14,$B$4:$M$4,0),Config!$B$7,Config!$B$8)) -> Pre | H3: =IF($B$14="","",IF((COLUMN()-1)<MATCH($B$14,$B$4:$M$4,0),Config!$B$7,Config!$B$8)) -> Post | I3: =IF($B$14="","",IF((COLUMN()-1)<MATCH($B$14,$B$4:$M$4,0),Config!$B$7,Config!$B$8)) -> Post | ... M3: =IF($B$14="","",IF((COLUMN()-1)<MATCH($B$14,$B$4:$M$4,0),Config!$B$7,Config!$B$8)) -> Post
A4: Metric | B4: Jan 2026 | C4: Feb 2026 | D4: Mar 2026 | E4: Apr 2026 | F4: May 2026 | G4: Jun 2026 | H4: Jul 2026 | I4: Aug 2026 | J4: Sep 2026 | K4: Oct 2026 | L4: Nov 2026 | M4: Dec 2026
A5: Spend | B5: =SUMIFS('Raw Data'!M:M,'Raw Data'!C:C,"2026-01") -> 4200 | C5: =SUMIFS('Raw Data'!M:M,'Raw Data'!C:C,"2026-02") -> 4100 | D5: =SUMIFS('Raw Data'!M:M,'Raw Data'!C:C,"2026-03") -> 4450 | E5: =SUMIFS('Raw Data'!M:M,'Raw Data'!C:C,"2026-04") -> 4600 | F5: =SUMIFS('Raw Data'!M:M,'Raw Data'!C:C,"2026-05") -> 4550 | G5: =SUMIFS('Raw Data'!M:M,'Raw Data'!C:C,"2026-06") -> 4700 | H5: =SUMIFS('Raw Data'!M:M,'Raw Data'!C:C,"2026-07") -> 6570 | I5: =SUMIFS('Raw Data'!M:M,'Raw Data'!C:C,"2026-08") -> 0 | J5: =SUMIFS('Raw Data'!M:M,'Raw Data'!C:C,"2026-09") -> 0 | K5: =SUMIFS('Raw Data'!M:M,'Raw Data'!C:C,"2026-10") -> 0 | L5: =SUMIFS('Raw Data'!M:M,'Raw Data'!C:C,"2026-11") -> 0 | M5: =SUMIFS('Raw Data'!M:M,'Raw Data'!C:C,"2026-12") -> 0
A6: Impressions | B6: =SUMIFS('Raw Data'!N:N,'Raw Data'!C:C,"2026-01") -> 185000 | C6: =SUMIFS('Raw Data'!N:N,'Raw Data'!C:C,"2026-02") -> 178000 | D6: =SUMIFS('Raw Data'!N:N,'Raw Data'!C:C,"2026-03") -> 192000 | E6: =SUMIFS('Raw Data'!N:N,'Raw Data'!C:C,"2026-04") -> 198000 | F6: =SUMIFS('Raw Data'!N:N,'Raw Data'!C:C,"2026-05") -> 201000 | G6: =SUMIFS('Raw Data'!N:N,'Raw Data'!C:C,"2026-06") -> 205000 | H6: =SUMIFS('Raw Data'!N:N,'Raw Data'!C:C,"2026-07") -> 301000 | I6: =SUMIFS('Raw Data'!N:N,'Raw Data'!C:C,"2026-08") -> 0 | J6: =SUMIFS('Raw Data'!N:N,'Raw Data'!C:C,"2026-09") -> 0 | K6: =SUMIFS('Raw Data'!N:N,'Raw Data'!C:C,"2026-10") -> 0 | L6: =SUMIFS('Raw Data'!N:N,'Raw Data'!C:C,"2026-11") -> 0 | M6: =SUMIFS('Raw Data'!N:N,'Raw Data'!C:C,"2026-12") -> 0
A7: Clicks | B7: =SUMIFS('Raw Data'!O:O,'Raw Data'!C:C,"2026-01") -> 6200 | C7: =SUMIFS('Raw Data'!O:O,'Raw Data'!C:C,"2026-02") -> 6050 | D7: =SUMIFS('Raw Data'!O:O,'Raw Data'!C:C,"2026-03") -> 6400 | E7: =SUMIFS('Raw Data'!O:O,'Raw Data'!C:C,"2026-04") -> 6550 | F7: =SUMIFS('Raw Data'!O:O,'Raw Data'!C:C,"2026-05") -> 6620 | G7: =SUMIFS('Raw Data'!O:O,'Raw Data'!C:C,"2026-06") -> 6800 | H7: =SUMIFS('Raw Data'!O:O,'Raw Data'!C:C,"2026-07") -> 9830 | I7: =SUMIFS('Raw Data'!O:O,'Raw Data'!C:C,"2026-08") -> 0 | J7: =SUMIFS('Raw Data'!O:O,'Raw Data'!C:C,"2026-09") -> 0 | K7: =SUMIFS('Raw Data'!O:O,'Raw Data'!C:C,"2026-10") -> 0 | L7: =SUMIFS('Raw Data'!O:O,'Raw Data'!C:C,"2026-11") -> 0 | M7: =SUMIFS('Raw Data'!O:O,'Raw Data'!C:C,"2026-12") -> 0
A8: Conversions | B8: =SUMIFS('Raw Data'!Q:Q,'Raw Data'!C:C,"2026-01") -> 148 | C8: =SUMIFS('Raw Data'!Q:Q,'Raw Data'!C:C,"2026-02") -> 142 | D8: =SUMIFS('Raw Data'!Q:Q,'Raw Data'!C:C,"2026-03") -> 155 | E8: =SUMIFS('Raw Data'!Q:Q,'Raw Data'!C:C,"2026-04") -> 160 | F8: =SUMIFS('Raw Data'!Q:Q,'Raw Data'!C:C,"2026-05") -> 158 | G8: =SUMIFS('Raw Data'!Q:Q,'Raw Data'!C:C,"2026-06") -> 165 | H8: =SUMIFS('Raw Data'!Q:Q,'Raw Data'!C:C,"2026-07") -> 235 | I8: =SUMIFS('Raw Data'!Q:Q,'Raw Data'!C:C,"2026-08") -> 0 | J8: =SUMIFS('Raw Data'!Q:Q,'Raw Data'!C:C,"2026-09") -> 0 | K8: =SUMIFS('Raw Data'!Q:Q,'Raw Data'!C:C,"2026-10") -> 0 | L8: =SUMIFS('Raw Data'!Q:Q,'Raw Data'!C:C,"2026-11") -> 0 | M8: =SUMIFS('Raw Data'!Q:Q,'Raw Data'!C:C,"2026-12") -> 0
A9: CPA (Spend / Conversions) | B9: =IF(B8=0,"",B5/B8) -> 28.378378 | C9: =IF(C8=0,"",C5/C8) -> 28.873239 | D9: =IF(D8=0,"",D5/D8) -> 28.709677 | E9: =IF(E8=0,"",E5/E8) -> 28.75 | F9: =IF(F8=0,"",F5/F8) -> 28.797468 | G9: =IF(G8=0,"",G5/G8) -> 28.484848 | H9: =IF(H8=0,"",H5/H8) -> 27.957447 | I9: =IF(I8=0,"",I5/I8) | ... M9: =IF(M8=0,"",M5/M8)
A10: CTR % (Clicks / Impressions) | B10: =IF(B6=0,"",B7/B6*100) -> 3.3513514 | C10: =IF(C6=0,"",C7/C6*100) -> 3.3988764 | D10: =IF(D6=0,"",D7/D6*100) -> 3.3333333 | E10: =IF(E6=0,"",E7/E6*100) -> 3.3080808 | F10: =IF(F6=0,"",F7/F6*100) -> 3.2935323 | G10: =IF(G6=0,"",G7/G6*100) -> 3.3170732 | H10: =IF(H6=0,"",H7/H6*100) -> 3.2657807 | I10: =IF(I6=0,"",I7/I6*100) | ... M10: =IF(M6=0,"",M7/M6*100)
A11: Conv. Rate % (Conv / Clicks) | B11: =IF(B7=0,"",B8/B7*100) -> 2.3870968 | C11: =IF(C7=0,"",C8/C7*100) -> 2.3471074 | D11: =IF(D7=0,"",D8/D7*100) -> 2.421875 | E11: =IF(E7=0,"",E8/E7*100) -> 2.4427481 | F11: =IF(F7=0,"",F8/F7*100) -> 2.3867069 | G11: =IF(G7=0,"",G8/G7*100) -> 2.4264706 | H11: =IF(H7=0,"",H8/H7*100) -> 2.3906409 | I11: =IF(I7=0,"",I8/I7*100) | ... M11: =IF(M7=0,"",M8/M7*100)
A13: Pre vs Post summary
A14: Post start month | B14: Jul 2026 | C14: ← select month (data validation). Pre = before this month; Post = this month → Dec.
A15: Metric | B15: Pre (before selected) | C15: Post (selected → Dec) | D15: Delta %
A16: Spend | B16: =IF($B$14="","",IF(MATCH($B$14,$B$4:$M$4,0)<=1,0,SUM(B5:INDEX(B5:M5,MATCH($B$14,$B$4:$M$4,0)-1)))) -> 26600 | C16: =IF($B$14="","",SUM(INDEX(B5:M5,MATCH($B$14,$B$4:$M$4,0)):M5)) -> 6570 | D16: =IF(OR(B16="",B16=0),"",(C16-B16)/B16) -> -0.75300752
A17: Clicks | B17: =IF($B$14="","",IF(MATCH($B$14,$B$4:$M$4,0)<=1,0,SUM(B7:INDEX(B7:M7,MATCH($B$14,$B$4:$M$4,0)-1)))) -> 38620 | C17: =IF($B$14="","",SUM(INDEX(B7:M7,MATCH($B$14,$B$4:$M$4,0)):M7)) -> 9830 | D17: =IF(OR(B17="",B17=0),"",(C17-B17)/B17) -> -0.74546867
A18: Conversions | B18: =IF($B$14="","",IF(MATCH($B$14,$B$4:$M$4,0)<=1,0,SUM(B8:INDEX(B8:M8,MATCH($B$14,$B$4:$M$4,0)-1)))) -> 928 | C18: =IF($B$14="","",SUM(INDEX(B8:M8,MATCH($B$14,$B$4:$M$4,0)):M8)) -> 235 | D18: =IF(OR(B18="",B18=0),"",(C18-B18)/B18) -> -0.74676724
A19: Avg monthly spend | B19: =IF($B$14="","",IF(MATCH($B$14,$B$4:$M$4,0)<=1,"",AVERAGE(B5:INDEX(B5:M5,MATCH($B$14,$B$4:$M$4,0)-1)))) -> 4433.3333 | C19: =IF($B$14="","",AVERAGE(INDEX(B5:M5,MATCH($B$14,$B$4:$M$4,0)):M5)) -> 1095 | D19: =IF(OR(B19="",B19=0),"",(C19-B19)/B19) -> -0.75300752
A20: CPA (total) | B20: =IF(OR(B16="",B18="",B18=0),"",B16/B18) -> 28.663793 | C20: =IF(OR(C16="",C18="",C18=0),"",C16/C18) -> 27.957447 | D20: =IF(OR(B20="",B20=0),"",(C20-B20)/B20) -> -0.024642457
A21: Avg monthly conversions | B21: =IF($B$14="","",IF(MATCH($B$14,$B$4:$M$4,0)<=1,"",AVERAGE(B8:INDEX(B8:M8,MATCH($B$14,$B$4:$M$4,0)-1)))) -> 154.66667 | C21: =IF($B$14="","",AVERAGE(INDEX(B8:M8,MATCH($B$14,$B$4:$M$4,0)):M8)) -> 39.166667 | D21: =IF(OR(B21="",B21=0),"",(C21-B21)/B21) -> -0.74676724
A22: Delta % = (Post − Pre) / Pre. Change B14 to re-cut the comparison (e.g. set to Apr 2026 to treat Apr–Dec as Post).
A23: Activity counts (by Type)
A24: Type | B24: Jan 2026 | C24: Feb 2026 | D24: Mar 2026 | E24: Apr 2026 | F24: May 2026 | G24: Jun 2026 | H24: Jul 2026 | I24: Aug 2026 | J24: Sep 2026 | K24: Oct 2026 | L24: Nov 2026 | M24: Dec 2026
A25: Strategy entries | B25: =COUNTIFS('Raw Data'!C:C,"2026-01",'Raw Data'!F:F,"Strategy") -> 0 | C25: =COUNTIFS('Raw Data'!C:C,"2026-02",'Raw Data'!F:F,"Strategy") -> 0 | D25: =COUNTIFS('Raw Data'!C:C,"2026-03",'Raw Data'!F:F,"Strategy") -> 0 | E25: =COUNTIFS('Raw Data'!C:C,"2026-04",'Raw Data'!F:F,"Strategy") -> 0 | F25: =COUNTIFS('Raw Data'!C:C,"2026-05",'Raw Data'!F:F,"Strategy") -> 0 | G25: =COUNTIFS('Raw Data'!C:C,"2026-06",'Raw Data'!F:F,"Strategy") -> 1 | H25: =COUNTIFS('Raw Data'!C:C,"2026-07",'Raw Data'!F:F,"Strategy") -> 1 | I25: =COUNTIFS('Raw Data'!C:C,"2026-08",'Raw Data'!F:F,"Strategy") -> 0 | J25: =COUNTIFS('Raw Data'!C:C,"2026-09",'Raw Data'!F:F,"Strategy") -> 0 | K25: =COUNTIFS('Raw Data'!C:C,"2026-10",'Raw Data'!F:F,"Strategy") -> 0 | L25: =COUNTIFS('Raw Data'!C:C,"2026-11",'Raw Data'!F:F,"Strategy") -> 0 | M25: =COUNTIFS('Raw Data'!C:C,"2026-12",'Raw Data'!F:F,"Strategy") -> 0
A26: Deployment entries | B26: =COUNTIFS('Raw Data'!C:C,"2026-01",'Raw Data'!F:F,"Deployment") -> 0 | C26: =COUNTIFS('Raw Data'!C:C,"2026-02",'Raw Data'!F:F,"Deployment") -> 0 | D26: =COUNTIFS('Raw Data'!C:C,"2026-03",'Raw Data'!F:F,"Deployment") -> 0 | E26: =COUNTIFS('Raw Data'!C:C,"2026-04",'Raw Data'!F:F,"Deployment") -> 0 | F26: =COUNTIFS('Raw Data'!C:C,"2026-05",'Raw Data'!F:F,"Deployment") -> 0 | G26: =COUNTIFS('Raw Data'!C:C,"2026-06",'Raw Data'!F:F,"Deployment") -> 0 | H26: =COUNTIFS('Raw Data'!C:C,"2026-07",'Raw Data'!F:F,"Deployment") -> 2 | I26: =COUNTIFS('Raw Data'!C:C,"2026-08",'Raw Data'!F:F,"Deployment") -> 0 | J26: =COUNTIFS('Raw Data'!C:C,"2026-09",'Raw Data'!F:F,"Deployment") -> 0 | K26: =COUNTIFS('Raw Data'!C:C,"2026-10",'Raw Data'!F:F,"Deployment") -> 0 | L26: =COUNTIFS('Raw Data'!C:C,"2026-11",'Raw Data'!F:F,"Deployment") -> 0 | M26: =COUNTIFS('Raw Data'!C:C,"2026-12",'Raw Data'!F:F,"Deployment") -> 0
A27: Performance Recap entries | B27: =COUNTIFS('Raw Data'!C:C,"2026-01",'Raw Data'!F:F,"Performance Recap") -> 1 | C27: =COUNTIFS('Raw Data'!C:C,"2026-02",'Raw Data'!F:F,"Performance Recap") -> 1 | D27: =COUNTIFS('Raw Data'!C:C,"2026-03",'Raw Data'!F:F,"Performance Recap") -> 1 | E27: =COUNTIFS('Raw Data'!C:C,"2026-04",'Raw Data'!F:F,"Performance Recap") -> 1 | F27: =COUNTIFS('Raw Data'!C:C,"2026-05",'Raw Data'!F:F,"Performance Recap") -> 1 | G27: =COUNTIFS('Raw Data'!C:C,"2026-06",'Raw Data'!F:F,"Performance Recap") -> 1 | H27: =COUNTIFS('Raw Data'!C:C,"2026-07",'Raw Data'!F:F,"Performance Recap") -> 1 | I27: =COUNTIFS('Raw Data'!C:C,"2026-08",'Raw Data'!F:F,"Performance Recap") -> 0 | J27: =COUNTIFS('Raw Data'!C:C,"2026-09",'Raw Data'!F:F,"Performance Recap") -> 0 | K27: =COUNTIFS('Raw Data'!C:C,"2026-10",'Raw Data'!F:F,"Performance Recap") -> 0 | L27: =COUNTIFS('Raw Data'!C:C,"2026-11",'Raw Data'!F:F,"Performance Recap") -> 0 | M27: =COUNTIFS('Raw Data'!C:C,"2026-12",'Raw Data'!F:F,"Performance Recap") -> 0

Sheet Reporting
A1: Reporting
A2: Charts removed. Use Monthly Metrics → Post start month dropdown (B14) to drive the Pre/Post summary table.
A4: Post start month (linked) | B4: ='[1]Monthly` Metrics'!B14 -> #REF!
A6: Pre vs Post (mirrors Monthly Metrics)
A7: Metric | B7: Pre | C7: Post | D7: Delta %
A8: ='Monthly Metrics'!A16 -> Spend | B8: ='Monthly Metrics'!B16 -> 26600 | C8: ='Monthly Metrics'!C16 -> 6570 | D8: ='Monthly Metrics'!D16 -> -0.75300752
A9: ='Monthly Metrics'!A17 -> Clicks | B9: ='Monthly Metrics'!B17 -> 38620 | C9: ='Monthly Metrics'!C17 -> 9830 | D9: ='Monthly Metrics'!D17 -> -0.74546867
A10: ='Monthly Metrics'!A18 -> Conversions | B10: ='Monthly Metrics'!B18 -> 928 | C10: ='Monthly Metrics'!C18 -> 235 | D10: ='Monthly Metrics'!D18 -> -0.74676724
A11: ='Monthly Metrics'!A19 -> Avg monthly spend | B11: ='Monthly Metrics'!B19 -> 4433.3333 | C11: ='Monthly Metrics'!C19 -> 1095 | D11: ='Monthly Metrics'!D19 -> -0.75300752
A12: ='Monthly Metrics'!A20 -> CPA (total) | B12: ='Monthly Metrics'!B20 -> 28.663793 | C12: ='Monthly Metrics'!C20 -> 27.957447 | D12: ='Monthly Metrics'!D20 -> -0.024642457
A13: ='Monthly Metrics'!A21 -> Avg monthly conversions | B13: ='Monthly Metrics'!B21 -> 154.66667 | C13: ='Monthly Metrics'!C21 -> 39.166667 | D13: ='Monthly Metrics'!D21 -> -0.74676724
A15: To change the cut: go to Monthly Metrics and use the dropdown in B14 (yellow cell). This view updates automatically.
